2022-09-26 15:54:31,678 - root - ERROR - (1130, "ursa.jagoanhosting.com' is not allowed to connect to this MariaDB server")
Traceback (most recent call last):
  File "/home/limaoper/bagi_pulsa/aplikasi/utils.py", line 49, in db_fetch
    return pd.read_sql(sql, con=db_con(), params=param)
  File "/home/limaoper/bagi_pulsa/aplikasi/utils.py", line 39, in db_con
    g.bagi_pulsa = _connect_db()
  File "/home/limaoper/bagi_pulsa/aplikasi/utils.py", line 15, in _connect_db
    cursorclass=pymysql.cursors.DictCursor
  File "/home/limaoper/virtualenv/bagi_pulsa/3.7/lib/python3.7/site-packages/pymysql/connections.py", line 353, in __init__
    self.connect()
  File "/home/limaoper/virtualenv/bagi_pulsa/3.7/lib/python3.7/site-packages/pymysql/connections.py", line 632, in connect
    self._get_server_information()
  File "/home/limaoper/virtualenv/bagi_pulsa/3.7/lib/python3.7/site-packages/pymysql/connections.py", line 1055, in _get_server_information
    packet = self._read_packet()
  File "/home/limaoper/virtualenv/bagi_pulsa/3.7/lib/python3.7/site-packages/pymysql/connections.py", line 725, in _read_packet
    packet.raise_for_error()
  File "/home/limaoper/virtualenv/bagi_pulsa/3.7/lib/python3.7/site-packages/pymysql/protocol.py", line 221, in raise_for_error
    err.raise_mysql_exception(self._data)
  File "/home/limaoper/virtualenv/bagi_pulsa/3.7/lib/python3.7/site-packages/pymysql/err.py", line 143, in raise_mysql_exception
    raise errorclass(errno, errval)
pymysql.err.OperationalError: (1130, "ursa.jagoanhosting.com' is not allowed to connect to this MariaDB server")
