2022-09-12 22:37:03,207 - root - ERROR - (1130, "ursa.jagoanhosting.com' is not allowed to connect to this MariaDB server")
Traceback (most recent call last):
  File "/home/limaoper/bagi_pulsa/aplikasi/utils.py", line 49, in db_fetch
    return pd.read_sql(sql, con=db_con(), params=param)
  File "/home/limaoper/bagi_pulsa/aplikasi/utils.py", line 39, in db_con
    g.bagi_pulsa = _connect_db()
  File "/home/limaoper/bagi_pulsa/aplikasi/utils.py", line 15, in _connect_db
    cursorclass=pymysql.cursors.DictCursor
  File "/home/limaoper/virtualenv/bagi_pulsa/3.7/lib/python3.7/site-packages/pymysql/connections.py", line 353, in __init__
    self.connect()
  File "/home/limaoper/virtualenv/bagi_pulsa/3.7/lib/python3.7/site-packages/pymysql/connections.py", line 632, in connect
    self._get_server_information()
  File "/home/limaoper/virtualenv/bagi_pulsa/3.7/lib/python3.7/site-packages/pymysql/connections.py", line 1055, in _get_server_information
    packet = self._read_packet()
  File "/home/limaoper/virtualenv/bagi_pulsa/3.7/lib/python3.7/site-packages/pymysql/connections.py", line 725, in _read_packet
    packet.raise_for_error()
  File "/home/limaoper/virtualenv/bagi_pulsa/3.7/lib/python3.7/site-packages/pymysql/protocol.py", line 221, in raise_for_error
    err.raise_mysql_exception(self._data)
  File "/home/limaoper/virtualenv/bagi_pulsa/3.7/lib/python3.7/site-packages/pymysql/err.py", line 143, in raise_mysql_exception
    raise errorclass(errno, errval)
pymysql.err.OperationalError: (1130, "ursa.jagoanhosting.com' is not allowed to connect to this MariaDB server")
2022-09-12 22:37:03,210 - aplikasi - ERROR - Exception on /master/get_akun_bank [POST]
Traceback (most recent call last):
  File "/home/limaoper/virtualenv/bagi_pulsa/3.7/lib/python3.7/site-packages/flask/app.py", line 2447, in wsgi_app
    response = self.full_dispatch_request()
  File "/home/limaoper/virtualenv/bagi_pulsa/3.7/lib/python3.7/site-packages/flask/app.py", line 1952, in full_dispatch_request
    rv = self.handle_user_exception(e)
  File "/home/limaoper/virtualenv/bagi_pulsa/3.7/lib/python3.7/site-packages/flask_cors/extension.py", line 165, in wrapped_function
    return cors_after_request(app.make_response(f(*args, **kwargs)))
  File "/home/limaoper/virtualenv/bagi_pulsa/3.7/lib/python3.7/site-packages/flask/app.py", line 1821, in handle_user_exception
    reraise(exc_type, exc_value, tb)
  File "/home/limaoper/virtualenv/bagi_pulsa/3.7/lib/python3.7/site-packages/flask/_compat.py", line 39, in reraise
    raise value
  File "/home/limaoper/virtualenv/bagi_pulsa/3.7/lib/python3.7/site-packages/flask/app.py", line 1950, in full_dispatch_request
    rv = self.dispatch_request()
  File "/home/limaoper/virtualenv/bagi_pulsa/3.7/lib/python3.7/site-packages/flask/app.py", line 1936, in dispatch_request
    return self.view_functions[rule.endpoint](**req.view_args)
  File "/home/limaoper/bagi_pulsa/aplikasi/master/routes.py", line 342, in get_akun_bank
    message = get_akun_bank.to_dict(orient='records')
AttributeError: 'NoneType' object has no attribute 'to_dict'
2022-09-13 08:07:48,694 - root - ERROR - (1130, "ursa.jagoanhosting.com' is not allowed to connect to this MariaDB server")
Traceback (most recent call last):
  File "/home/limaoper/bagi_pulsa/aplikasi/utils.py", line 49, in db_fetch
    return pd.read_sql(sql, con=db_con(), params=param)
  File "/home/limaoper/bagi_pulsa/aplikasi/utils.py", line 39, in db_con
    g.bagi_pulsa = _connect_db()
  File "/home/limaoper/bagi_pulsa/aplikasi/utils.py", line 15, in _connect_db
    cursorclass=pymysql.cursors.DictCursor
  File "/home/limaoper/virtualenv/bagi_pulsa/3.7/lib/python3.7/site-packages/pymysql/connections.py", line 353, in __init__
    self.connect()
  File "/home/limaoper/virtualenv/bagi_pulsa/3.7/lib/python3.7/site-packages/pymysql/connections.py", line 632, in connect
    self._get_server_information()
  File "/home/limaoper/virtualenv/bagi_pulsa/3.7/lib/python3.7/site-packages/pymysql/connections.py", line 1055, in _get_server_information
    packet = self._read_packet()
  File "/home/limaoper/virtualenv/bagi_pulsa/3.7/lib/python3.7/site-packages/pymysql/connections.py", line 725, in _read_packet
    packet.raise_for_error()
  File "/home/limaoper/virtualenv/bagi_pulsa/3.7/lib/python3.7/site-packages/pymysql/protocol.py", line 221, in raise_for_error
    err.raise_mysql_exception(self._data)
  File "/home/limaoper/virtualenv/bagi_pulsa/3.7/lib/python3.7/site-packages/pymysql/err.py", line 143, in raise_mysql_exception
    raise errorclass(errno, errval)
pymysql.err.OperationalError: (1130, "ursa.jagoanhosting.com' is not allowed to connect to this MariaDB server")
2022-09-13 08:07:48,700 - aplikasi - ERROR - Exception on /master/get_akun_bank [POST]
Traceback (most recent call last):
  File "/home/limaoper/virtualenv/bagi_pulsa/3.7/lib/python3.7/site-packages/flask/app.py", line 2447, in wsgi_app
    response = self.full_dispatch_request()
  File "/home/limaoper/virtualenv/bagi_pulsa/3.7/lib/python3.7/site-packages/flask/app.py", line 1952, in full_dispatch_request
    rv = self.handle_user_exception(e)
  File "/home/limaoper/virtualenv/bagi_pulsa/3.7/lib/python3.7/site-packages/flask_cors/extension.py", line 165, in wrapped_function
    return cors_after_request(app.make_response(f(*args, **kwargs)))
  File "/home/limaoper/virtualenv/bagi_pulsa/3.7/lib/python3.7/site-packages/flask/app.py", line 1821, in handle_user_exception
    reraise(exc_type, exc_value, tb)
  File "/home/limaoper/virtualenv/bagi_pulsa/3.7/lib/python3.7/site-packages/flask/_compat.py", line 39, in reraise
    raise value
  File "/home/limaoper/virtualenv/bagi_pulsa/3.7/lib/python3.7/site-packages/flask/app.py", line 1950, in full_dispatch_request
    rv = self.dispatch_request()
  File "/home/limaoper/virtualenv/bagi_pulsa/3.7/lib/python3.7/site-packages/flask/app.py", line 1936, in dispatch_request
    return self.view_functions[rule.endpoint](**req.view_args)
  File "/home/limaoper/bagi_pulsa/aplikasi/master/routes.py", line 342, in get_akun_bank
    message = get_akun_bank.to_dict(orient='records')
AttributeError: 'NoneType' object has no attribute 'to_dict'
2022-09-13 14:24:53,389 - aplikasi - ERROR - Exception on /master/post_akun_bank [POST]
Traceback (most recent call last):
  File "/home/limaoper/virtualenv/bagi_pulsa/3.7/lib/python3.7/site-packages/flask/app.py", line 2447, in wsgi_app
    response = self.full_dispatch_request()
  File "/home/limaoper/virtualenv/bagi_pulsa/3.7/lib/python3.7/site-packages/flask/app.py", line 1952, in full_dispatch_request
    rv = self.handle_user_exception(e)
  File "/home/limaoper/virtualenv/bagi_pulsa/3.7/lib/python3.7/site-packages/flask_cors/extension.py", line 165, in wrapped_function
    return cors_after_request(app.make_response(f(*args, **kwargs)))
  File "/home/limaoper/virtualenv/bagi_pulsa/3.7/lib/python3.7/site-packages/flask/app.py", line 1821, in handle_user_exception
    reraise(exc_type, exc_value, tb)
  File "/home/limaoper/virtualenv/bagi_pulsa/3.7/lib/python3.7/site-packages/flask/_compat.py", line 39, in reraise
    raise value
  File "/home/limaoper/virtualenv/bagi_pulsa/3.7/lib/python3.7/site-packages/flask/app.py", line 1950, in full_dispatch_request
    rv = self.dispatch_request()
  File "/home/limaoper/virtualenv/bagi_pulsa/3.7/lib/python3.7/site-packages/flask/app.py", line 1936, in dispatch_request
    return self.view_functions[rule.endpoint](**req.view_args)
  File "/home/limaoper/bagi_pulsa/aplikasi/master/routes.py", line 300, in post_akun_bank
    kode_bank = hsl_data_bank[0]['kode_bank']
IndexError: list index out of range
2022-09-13 14:24:55,567 - aplikasi - ERROR - Exception on /master/post_akun_bank [POST]
Traceback (most recent call last):
  File "/home/limaoper/virtualenv/bagi_pulsa/3.7/lib/python3.7/site-packages/flask/app.py", line 2447, in wsgi_app
    response = self.full_dispatch_request()
  File "/home/limaoper/virtualenv/bagi_pulsa/3.7/lib/python3.7/site-packages/flask/app.py", line 1952, in full_dispatch_request
    rv = self.handle_user_exception(e)
  File "/home/limaoper/virtualenv/bagi_pulsa/3.7/lib/python3.7/site-packages/flask_cors/extension.py", line 165, in wrapped_function
    return cors_after_request(app.make_response(f(*args, **kwargs)))
  File "/home/limaoper/virtualenv/bagi_pulsa/3.7/lib/python3.7/site-packages/flask/app.py", line 1821, in handle_user_exception
    reraise(exc_type, exc_value, tb)
  File "/home/limaoper/virtualenv/bagi_pulsa/3.7/lib/python3.7/site-packages/flask/_compat.py", line 39, in reraise
    raise value
  File "/home/limaoper/virtualenv/bagi_pulsa/3.7/lib/python3.7/site-packages/flask/app.py", line 1950, in full_dispatch_request
    rv = self.dispatch_request()
  File "/home/limaoper/virtualenv/bagi_pulsa/3.7/lib/python3.7/site-packages/flask/app.py", line 1936, in dispatch_request
    return self.view_functions[rule.endpoint](**req.view_args)
  File "/home/limaoper/bagi_pulsa/aplikasi/master/routes.py", line 300, in post_akun_bank
    kode_bank = hsl_data_bank[0]['kode_bank']
IndexError: list index out of range
2022-09-13 14:24:56,409 - aplikasi - ERROR - Exception on /master/post_akun_bank [POST]
Traceback (most recent call last):
  File "/home/limaoper/virtualenv/bagi_pulsa/3.7/lib/python3.7/site-packages/flask/app.py", line 2447, in wsgi_app
    response = self.full_dispatch_request()
  File "/home/limaoper/virtualenv/bagi_pulsa/3.7/lib/python3.7/site-packages/flask/app.py", line 1952, in full_dispatch_request
    rv = self.handle_user_exception(e)
  File "/home/limaoper/virtualenv/bagi_pulsa/3.7/lib/python3.7/site-packages/flask_cors/extension.py", line 165, in wrapped_function
    return cors_after_request(app.make_response(f(*args, **kwargs)))
  File "/home/limaoper/virtualenv/bagi_pulsa/3.7/lib/python3.7/site-packages/flask/app.py", line 1821, in handle_user_exception
    reraise(exc_type, exc_value, tb)
  File "/home/limaoper/virtualenv/bagi_pulsa/3.7/lib/python3.7/site-packages/flask/_compat.py", line 39, in reraise
    raise value
  File "/home/limaoper/virtualenv/bagi_pulsa/3.7/lib/python3.7/site-packages/flask/app.py", line 1950, in full_dispatch_request
    rv = self.dispatch_request()
  File "/home/limaoper/virtualenv/bagi_pulsa/3.7/lib/python3.7/site-packages/flask/app.py", line 1936, in dispatch_request
    return self.view_functions[rule.endpoint](**req.view_args)
  File "/home/limaoper/bagi_pulsa/aplikasi/master/routes.py", line 300, in post_akun_bank
    kode_bank = hsl_data_bank[0]['kode_bank']
IndexError: list index out of range
2022-09-13 14:24:56,663 - aplikasi - ERROR - Exception on /master/post_akun_bank [POST]
Traceback (most recent call last):
  File "/home/limaoper/virtualenv/bagi_pulsa/3.7/lib/python3.7/site-packages/flask/app.py", line 2447, in wsgi_app
    response = self.full_dispatch_request()
  File "/home/limaoper/virtualenv/bagi_pulsa/3.7/lib/python3.7/site-packages/flask/app.py", line 1952, in full_dispatch_request
    rv = self.handle_user_exception(e)
  File "/home/limaoper/virtualenv/bagi_pulsa/3.7/lib/python3.7/site-packages/flask_cors/extension.py", line 165, in wrapped_function
    return cors_after_request(app.make_response(f(*args, **kwargs)))
  File "/home/limaoper/virtualenv/bagi_pulsa/3.7/lib/python3.7/site-packages/flask/app.py", line 1821, in handle_user_exception
    reraise(exc_type, exc_value, tb)
  File "/home/limaoper/virtualenv/bagi_pulsa/3.7/lib/python3.7/site-packages/flask/_compat.py", line 39, in reraise
    raise value
  File "/home/limaoper/virtualenv/bagi_pulsa/3.7/lib/python3.7/site-packages/flask/app.py", line 1950, in full_dispatch_request
    rv = self.dispatch_request()
  File "/home/limaoper/virtualenv/bagi_pulsa/3.7/lib/python3.7/site-packages/flask/app.py", line 1936, in dispatch_request
    return self.view_functions[rule.endpoint](**req.view_args)
  File "/home/limaoper/bagi_pulsa/aplikasi/master/routes.py", line 300, in post_akun_bank
    kode_bank = hsl_data_bank[0]['kode_bank']
IndexError: list index out of range
2022-09-13 14:24:56,864 - aplikasi - ERROR - Exception on /master/post_akun_bank [POST]
Traceback (most recent call last):
  File "/home/limaoper/virtualenv/bagi_pulsa/3.7/lib/python3.7/site-packages/flask/app.py", line 2447, in wsgi_app
    response = self.full_dispatch_request()
  File "/home/limaoper/virtualenv/bagi_pulsa/3.7/lib/python3.7/site-packages/flask/app.py", line 1952, in full_dispatch_request
    rv = self.handle_user_exception(e)
  File "/home/limaoper/virtualenv/bagi_pulsa/3.7/lib/python3.7/site-packages/flask_cors/extension.py", line 165, in wrapped_function
    return cors_after_request(app.make_response(f(*args, **kwargs)))
  File "/home/limaoper/virtualenv/bagi_pulsa/3.7/lib/python3.7/site-packages/flask/app.py", line 1821, in handle_user_exception
    reraise(exc_type, exc_value, tb)
  File "/home/limaoper/virtualenv/bagi_pulsa/3.7/lib/python3.7/site-packages/flask/_compat.py", line 39, in reraise
    raise value
  File "/home/limaoper/virtualenv/bagi_pulsa/3.7/lib/python3.7/site-packages/flask/app.py", line 1950, in full_dispatch_request
    rv = self.dispatch_request()
  File "/home/limaoper/virtualenv/bagi_pulsa/3.7/lib/python3.7/site-packages/flask/app.py", line 1936, in dispatch_request
    return self.view_functions[rule.endpoint](**req.view_args)
  File "/home/limaoper/bagi_pulsa/aplikasi/master/routes.py", line 300, in post_akun_bank
    kode_bank = hsl_data_bank[0]['kode_bank']
IndexError: list index out of range
2022-09-14 06:22:10,597 - root - ERROR - (1130, "ursa.jagoanhosting.com' is not allowed to connect to this MariaDB server")
Traceback (most recent call last):
  File "/home/limaoper/bagi_pulsa/aplikasi/utils.py", line 49, in db_fetch
    return pd.read_sql(sql, con=db_con(), params=param)
  File "/home/limaoper/bagi_pulsa/aplikasi/utils.py", line 39, in db_con
    g.bagi_pulsa = _connect_db()
  File "/home/limaoper/bagi_pulsa/aplikasi/utils.py", line 15, in _connect_db
    cursorclass=pymysql.cursors.DictCursor
  File "/home/limaoper/virtualenv/bagi_pulsa/3.7/lib/python3.7/site-packages/pymysql/connections.py", line 353, in __init__
    self.connect()
  File "/home/limaoper/virtualenv/bagi_pulsa/3.7/lib/python3.7/site-packages/pymysql/connections.py", line 632, in connect
    self._get_server_information()
  File "/home/limaoper/virtualenv/bagi_pulsa/3.7/lib/python3.7/site-packages/pymysql/connections.py", line 1055, in _get_server_information
    packet = self._read_packet()
  File "/home/limaoper/virtualenv/bagi_pulsa/3.7/lib/python3.7/site-packages/pymysql/connections.py", line 725, in _read_packet
    packet.raise_for_error()
  File "/home/limaoper/virtualenv/bagi_pulsa/3.7/lib/python3.7/site-packages/pymysql/protocol.py", line 221, in raise_for_error
    err.raise_mysql_exception(self._data)
  File "/home/limaoper/virtualenv/bagi_pulsa/3.7/lib/python3.7/site-packages/pymysql/err.py", line 143, in raise_mysql_exception
    raise errorclass(errno, errval)
pymysql.err.OperationalError: (1130, "ursa.jagoanhosting.com' is not allowed to connect to this MariaDB server")
2022-09-14 06:22:10,597 - root - ERROR - (1130, "ursa.jagoanhosting.com' is not allowed to connect to this MariaDB server")
Traceback (most recent call last):
  File "/home/limaoper/bagi_pulsa/aplikasi/utils.py", line 49, in db_fetch
    return pd.read_sql(sql, con=db_con(), params=param)
  File "/home/limaoper/bagi_pulsa/aplikasi/utils.py", line 39, in db_con
    g.bagi_pulsa = _connect_db()
  File "/home/limaoper/bagi_pulsa/aplikasi/utils.py", line 15, in _connect_db
    cursorclass=pymysql.cursors.DictCursor
  File "/home/limaoper/virtualenv/bagi_pulsa/3.7/lib/python3.7/site-packages/pymysql/connections.py", line 353, in __init__
    self.connect()
  File "/home/limaoper/virtualenv/bagi_pulsa/3.7/lib/python3.7/site-packages/pymysql/connections.py", line 632, in connect
    self._get_server_information()
  File "/home/limaoper/virtualenv/bagi_pulsa/3.7/lib/python3.7/site-packages/pymysql/connections.py", line 1055, in _get_server_information
    packet = self._read_packet()
  File "/home/limaoper/virtualenv/bagi_pulsa/3.7/lib/python3.7/site-packages/pymysql/connections.py", line 725, in _read_packet
    packet.raise_for_error()
  File "/home/limaoper/virtualenv/bagi_pulsa/3.7/lib/python3.7/site-packages/pymysql/protocol.py", line 221, in raise_for_error
    err.raise_mysql_exception(self._data)
  File "/home/limaoper/virtualenv/bagi_pulsa/3.7/lib/python3.7/site-packages/pymysql/err.py", line 143, in raise_mysql_exception
    raise errorclass(errno, errval)
pymysql.err.OperationalError: (1130, "ursa.jagoanhosting.com' is not allowed to connect to this MariaDB server")
2022-09-14 06:22:10,597 - root - ERROR - (1130, "ursa.jagoanhosting.com' is not allowed to connect to this MariaDB server")
Traceback (most recent call last):
  File "/home/limaoper/bagi_pulsa/aplikasi/utils.py", line 49, in db_fetch
    return pd.read_sql(sql, con=db_con(), params=param)
  File "/home/limaoper/bagi_pulsa/aplikasi/utils.py", line 39, in db_con
    g.bagi_pulsa = _connect_db()
  File "/home/limaoper/bagi_pulsa/aplikasi/utils.py", line 15, in _connect_db
    cursorclass=pymysql.cursors.DictCursor
  File "/home/limaoper/virtualenv/bagi_pulsa/3.7/lib/python3.7/site-packages/pymysql/connections.py", line 353, in __init__
    self.connect()
  File "/home/limaoper/virtualenv/bagi_pulsa/3.7/lib/python3.7/site-packages/pymysql/connections.py", line 632, in connect
    self._get_server_information()
  File "/home/limaoper/virtualenv/bagi_pulsa/3.7/lib/python3.7/site-packages/pymysql/connections.py", line 1055, in _get_server_information
    packet = self._read_packet()
  File "/home/limaoper/virtualenv/bagi_pulsa/3.7/lib/python3.7/site-packages/pymysql/connections.py", line 725, in _read_packet
    packet.raise_for_error()
  File "/home/limaoper/virtualenv/bagi_pulsa/3.7/lib/python3.7/site-packages/pymysql/protocol.py", line 221, in raise_for_error
    err.raise_mysql_exception(self._data)
  File "/home/limaoper/virtualenv/bagi_pulsa/3.7/lib/python3.7/site-packages/pymysql/err.py", line 143, in raise_mysql_exception
    raise errorclass(errno, errval)
pymysql.err.OperationalError: (1130, "ursa.jagoanhosting.com' is not allowed to connect to this MariaDB server")
2022-09-14 06:22:10,602 - aplikasi - ERROR - Exception on /master/banner [GET]
Traceback (most recent call last):
  File "/home/limaoper/virtualenv/bagi_pulsa/3.7/lib/python3.7/site-packages/flask/app.py", line 2447, in wsgi_app
    response = self.full_dispatch_request()
  File "/home/limaoper/virtualenv/bagi_pulsa/3.7/lib/python3.7/site-packages/flask/app.py", line 1952, in full_dispatch_request
    rv = self.handle_user_exception(e)
  File "/home/limaoper/virtualenv/bagi_pulsa/3.7/lib/python3.7/site-packages/flask_cors/extension.py", line 165, in wrapped_function
    return cors_after_request(app.make_response(f(*args, **kwargs)))
  File "/home/limaoper/virtualenv/bagi_pulsa/3.7/lib/python3.7/site-packages/flask/app.py", line 1821, in handle_user_exception
    reraise(exc_type, exc_value, tb)
  File "/home/limaoper/virtualenv/bagi_pulsa/3.7/lib/python3.7/site-packages/flask/_compat.py", line 39, in reraise
    raise value
  File "/home/limaoper/virtualenv/bagi_pulsa/3.7/lib/python3.7/site-packages/flask/app.py", line 1950, in full_dispatch_request
    rv = self.dispatch_request()
  File "/home/limaoper/virtualenv/bagi_pulsa/3.7/lib/python3.7/site-packages/flask/app.py", line 1936, in dispatch_request
    return self.view_functions[rule.endpoint](**req.view_args)
  File "/home/limaoper/bagi_pulsa/aplikasi/master/routes.py", line 405, in get_banner
    message = get_banner.to_dict(orient='records')
AttributeError: 'NoneType' object has no attribute 'to_dict'
2022-09-14 06:22:10,602 - aplikasi - ERROR - Exception on /master/status_service [GET]
Traceback (most recent call last):
  File "/home/limaoper/virtualenv/bagi_pulsa/3.7/lib/python3.7/site-packages/flask/app.py", line 2447, in wsgi_app
    response = self.full_dispatch_request()
  File "/home/limaoper/virtualenv/bagi_pulsa/3.7/lib/python3.7/site-packages/flask/app.py", line 1952, in full_dispatch_request
    rv = self.handle_user_exception(e)
  File "/home/limaoper/virtualenv/bagi_pulsa/3.7/lib/python3.7/site-packages/flask_cors/extension.py", line 165, in wrapped_function
    return cors_after_request(app.make_response(f(*args, **kwargs)))
  File "/home/limaoper/virtualenv/bagi_pulsa/3.7/lib/python3.7/site-packages/flask/app.py", line 1821, in handle_user_exception
    reraise(exc_type, exc_value, tb)
  File "/home/limaoper/virtualenv/bagi_pulsa/3.7/lib/python3.7/site-packages/flask/_compat.py", line 39, in reraise
    raise value
  File "/home/limaoper/virtualenv/bagi_pulsa/3.7/lib/python3.7/site-packages/flask/app.py", line 1950, in full_dispatch_request
    rv = self.dispatch_request()
  File "/home/limaoper/virtualenv/bagi_pulsa/3.7/lib/python3.7/site-packages/flask/app.py", line 1936, in dispatch_request
    return self.view_functions[rule.endpoint](**req.view_args)
  File "/home/limaoper/bagi_pulsa/aplikasi/master/routes.py", line 148, in status_service
    data = data_status.to_dict(orient='records')
AttributeError: 'NoneType' object has no attribute 'to_dict'
2022-09-14 06:22:10,602 - aplikasi - ERROR - Exception on /master/status_provider [GET]
Traceback (most recent call last):
  File "/home/limaoper/virtualenv/bagi_pulsa/3.7/lib/python3.7/site-packages/flask/app.py", line 2447, in wsgi_app
    response = self.full_dispatch_request()
  File "/home/limaoper/virtualenv/bagi_pulsa/3.7/lib/python3.7/site-packages/flask/app.py", line 1952, in full_dispatch_request
    rv = self.handle_user_exception(e)
  File "/home/limaoper/virtualenv/bagi_pulsa/3.7/lib/python3.7/site-packages/flask_cors/extension.py", line 165, in wrapped_function
    return cors_after_request(app.make_response(f(*args, **kwargs)))
  File "/home/limaoper/virtualenv/bagi_pulsa/3.7/lib/python3.7/site-packages/flask/app.py", line 1821, in handle_user_exception
    reraise(exc_type, exc_value, tb)
  File "/home/limaoper/virtualenv/bagi_pulsa/3.7/lib/python3.7/site-packages/flask/_compat.py", line 39, in reraise
    raise value
  File "/home/limaoper/virtualenv/bagi_pulsa/3.7/lib/python3.7/site-packages/flask/app.py", line 1950, in full_dispatch_request
    rv = self.dispatch_request()
  File "/home/limaoper/virtualenv/bagi_pulsa/3.7/lib/python3.7/site-packages/flask/app.py", line 1936, in dispatch_request
    return self.view_functions[rule.endpoint](**req.view_args)
  File "/home/limaoper/bagi_pulsa/aplikasi/master/routes.py", line 79, in status_provider
    data = data_status.to_dict(orient='records')
AttributeError: 'NoneType' object has no attribute 'to_dict'
2022-09-14 10:59:22,810 - root - ERROR - (1130, "ursa.jagoanhosting.com' is not allowed to connect to this MariaDB server")
Traceback (most recent call last):
  File "/home/limaoper/bagi_pulsa/aplikasi/utils.py", line 49, in db_fetch
    return pd.read_sql(sql, con=db_con(), params=param)
  File "/home/limaoper/bagi_pulsa/aplikasi/utils.py", line 39, in db_con
    g.bagi_pulsa = _connect_db()
  File "/home/limaoper/bagi_pulsa/aplikasi/utils.py", line 15, in _connect_db
    cursorclass=pymysql.cursors.DictCursor
  File "/home/limaoper/virtualenv/bagi_pulsa/3.7/lib/python3.7/site-packages/pymysql/connections.py", line 353, in __init__
    self.connect()
  File "/home/limaoper/virtualenv/bagi_pulsa/3.7/lib/python3.7/site-packages/pymysql/connections.py", line 632, in connect
    self._get_server_information()
  File "/home/limaoper/virtualenv/bagi_pulsa/3.7/lib/python3.7/site-packages/pymysql/connections.py", line 1055, in _get_server_information
    packet = self._read_packet()
  File "/home/limaoper/virtualenv/bagi_pulsa/3.7/lib/python3.7/site-packages/pymysql/connections.py", line 725, in _read_packet
    packet.raise_for_error()
  File "/home/limaoper/virtualenv/bagi_pulsa/3.7/lib/python3.7/site-packages/pymysql/protocol.py", line 221, in raise_for_error
    err.raise_mysql_exception(self._data)
  File "/home/limaoper/virtualenv/bagi_pulsa/3.7/lib/python3.7/site-packages/pymysql/err.py", line 143, in raise_mysql_exception
    raise errorclass(errno, errval)
pymysql.err.OperationalError: (1130, "ursa.jagoanhosting.com' is not allowed to connect to this MariaDB server")
2022-09-14 22:08:55,997 - root - ERROR - (1130, "ursa.jagoanhosting.com' is not allowed to connect to this MariaDB server")
Traceback (most recent call last):
  File "/home/limaoper/bagi_pulsa/aplikasi/utils.py", line 49, in db_fetch
    return pd.read_sql(sql, con=db_con(), params=param)
  File "/home/limaoper/bagi_pulsa/aplikasi/utils.py", line 39, in db_con
    g.bagi_pulsa = _connect_db()
  File "/home/limaoper/bagi_pulsa/aplikasi/utils.py", line 15, in _connect_db
    cursorclass=pymysql.cursors.DictCursor
  File "/home/limaoper/virtualenv/bagi_pulsa/3.7/lib/python3.7/site-packages/pymysql/connections.py", line 353, in __init__
    self.connect()
  File "/home/limaoper/virtualenv/bagi_pulsa/3.7/lib/python3.7/site-packages/pymysql/connections.py", line 632, in connect
    self._get_server_information()
  File "/home/limaoper/virtualenv/bagi_pulsa/3.7/lib/python3.7/site-packages/pymysql/connections.py", line 1055, in _get_server_information
    packet = self._read_packet()
  File "/home/limaoper/virtualenv/bagi_pulsa/3.7/lib/python3.7/site-packages/pymysql/connections.py", line 725, in _read_packet
    packet.raise_for_error()
  File "/home/limaoper/virtualenv/bagi_pulsa/3.7/lib/python3.7/site-packages/pymysql/protocol.py", line 221, in raise_for_error
    err.raise_mysql_exception(self._data)
  File "/home/limaoper/virtualenv/bagi_pulsa/3.7/lib/python3.7/site-packages/pymysql/err.py", line 143, in raise_mysql_exception
    raise errorclass(errno, errval)
pymysql.err.OperationalError: (1130, "ursa.jagoanhosting.com' is not allowed to connect to this MariaDB server")
2022-09-14 22:08:56,001 - aplikasi - ERROR - Exception on /master/post_transaksi [POST]
Traceback (most recent call last):
  File "/home/limaoper/virtualenv/bagi_pulsa/3.7/lib/python3.7/site-packages/flask/app.py", line 2447, in wsgi_app
    response = self.full_dispatch_request()
  File "/home/limaoper/virtualenv/bagi_pulsa/3.7/lib/python3.7/site-packages/flask/app.py", line 1952, in full_dispatch_request
    rv = self.handle_user_exception(e)
  File "/home/limaoper/virtualenv/bagi_pulsa/3.7/lib/python3.7/site-packages/flask_cors/extension.py", line 165, in wrapped_function
    return cors_after_request(app.make_response(f(*args, **kwargs)))
  File "/home/limaoper/virtualenv/bagi_pulsa/3.7/lib/python3.7/site-packages/flask/app.py", line 1821, in handle_user_exception
    reraise(exc_type, exc_value, tb)
  File "/home/limaoper/virtualenv/bagi_pulsa/3.7/lib/python3.7/site-packages/flask/_compat.py", line 39, in reraise
    raise value
  File "/home/limaoper/virtualenv/bagi_pulsa/3.7/lib/python3.7/site-packages/flask/app.py", line 1950, in full_dispatch_request
    rv = self.dispatch_request()
  File "/home/limaoper/virtualenv/bagi_pulsa/3.7/lib/python3.7/site-packages/flask/app.py", line 1936, in dispatch_request
    return self.view_functions[rule.endpoint](**req.view_args)
  File "/home/limaoper/bagi_pulsa/aplikasi/master/routes.py", line 204, in data_transaksi
    hsl_data_bank = data_bank.to_dict(orient='records')
AttributeError: 'NoneType' object has no attribute 'to_dict'
